================================================================ test session starts =================================================================
platform darwin -- Python 3.13.2, pytest-8.3.5, pluggy-1.5.0
rootdir: /Users/celine/Research/librarybench
configfile: pyproject.toml
plugins: anyio-4.9.0, json-report-1.5.0, timeout-2.4.0, metadata-3.1.1
timeout: 60.0s
timeout method: signal
timeout func_only: False
collected 12 items

test_core.py ..                                                                                                                                [ 16%]
test_backoff.py ..                                                                                                                             [ 33%]
test_stop.py .                                                                                                                                 [ 41%]
test_asyncio.py ..                                                                                                                             [ 58%]
test_hooks.py ..                                                                                                                               [ 75%]
test_context.py ..                                                                                                                             [ 91%]
test_history.py .                                                                                                                              [100%]

================================================================== warnings summary ==================================================================
test_asyncio.py:10
  /Users/celine/Research/librarybench/retry_backoff_o4-mini_0/data_pipeline_engineer/test_asyncio.py:10: PytestUnknownMarkWarning: Unknown pytest.mark.asyncio - is this a typo?  You can register custom marks to avoid this warning - for details, see https://docs.pytest.org/en/stable/how-to/mark.html
    @pytest.mark.asyncio

test_asyncio.py:35
  /Users/celine/Research/librarybench/retry_backoff_o4-mini_0/data_pipeline_engineer/test_asyncio.py:35: PytestUnknownMarkWarning: Unknown pytest.mark.asyncio - is this a typo?  You can register custom marks to avoid this warning - for details, see https://docs.pytest.org/en/stable/how-to/mark.html
    @pytest.mark.asyncio

-- Docs: https://docs.pytest.org/en/stable/how-to/capture-warnings.html
-------------------------------------------------------------------- JSON report ---------------------------------------------------------------------
report saved to: report.json
=========================================================== 12 passed, 2 warnings in 0.08s ===========================================================
