{"created": 1746554719.859311, "duration": 2.628330945968628, "exitcode": 1, "root": "/Users/celine/Research/librarybench", "environment": {}, "summary": {"failed": 6, "passed": 9, "total": 15, "collected": 15}, "collectors": [{"nodeid": "", "outcome": "passed", "result": [{"nodeid": "workflow_orchestration_o4-mini_group0_3/Product_Manager/tests/test_api.py", "type": "Module"}, {"nodeid": "workflow_orchestration_o4-mini_group0_3/Product_Manager/tests/test_manager.py", "type": "Module"}, {"nodeid": "workflow_orchestration_o4-mini_group0_3/Data_Scientist/tests/test_task.py", "type": "Module"}, {"nodeid": "workflow_orchestration_o4-mini_group0_3/Data_Scientist/tests/test_workflow.py", "type": "Module"}, {"nodeid": "workflow_orchestration_o4-mini_group0_3/Data_Scientist/tests/test_api.py", "type": "Module"}, {"nodeid": "workflow_orchestration_o4-mini_group0_3/Data_Engineer/test_utils.py", "type": "Module"}, {"nodeid": "workflow_orchestration_o4-mini_group0_3/Data_Engineer/test_task.py", "type": "Module"}, {"nodeid": "workflow_orchestration_o4-mini_group0_3/Data_Engineer/test_auth.py", "type": "Module"}, {"nodeid": "workflow_orchestration_o4-mini_group0_3/Data_Engineer/test_ui.py", "type": "Module"}, {"nodeid": "workflow_orchestration_o4-mini_group0_3/Data_Engineer/test_scheduler.py", "type": "Module"}, {"nodeid": "workflow_orchestration_o4-mini_group0_3/Data_Engineer/test_manager.py", "type": "Module"}]}, {"nodeid": "workflow_orchestration_o4-mini_group0_3/Product_Manager/tests/test_api.py", "outcome": "failed", "result": [], "longrepr": "ImportError while importing test module '/Users/celine/Research/librarybench/workflow_orchestration_o4-mini_group0_3/Product_Manager/tests/test_api.py'.\nHint: make sure your test modules/packages have valid Python names.\nTraceback:\n../../../miniconda3/envs/library/lib/python3.13/importlib/__init__.py:88: in import_module\n    return _bootstrap._gcd_import(name[level:], package, level)\nProduct_Manager/tests/test_api.py:3: in <module>\n    from Product_Manager.task_manager.api import app, manager\nProduct_Manager/task_manager/api.py:1: in <module>\n    from flask import Flask\nE   ModuleNotFoundError: No module named 'flask'"}, {"nodeid": "workflow_orchestration_o4-mini_group0_3/Product_Manager/tests/test_manager.py", "outcome": "passed", "result": [{"nodeid": "workflow_orchestration_o4-mini_group0_3/Product_Manager/tests/test_manager.py::test_queue_task_success", "type": "Function", "lineno": 4}, {"nodeid": "workflow_orchestration_o4-mini_group0_3/Product_Manager/tests/test_manager.py::test_retry_failed_then_success", "type": "Function", "lineno": 16}, {"nodeid": "workflow_orchestration_o4-mini_group0_3/Product_Manager/tests/test_manager.py::test_retry_exhausted_sends_alert", "type": "Function", "lineno": 31}, {"nodeid": "workflow_orchestration_o4-mini_group0_3/Product_Manager/tests/test_manager.py::test_timeout", "type": "Function", "lineno": 45}, {"nodeid": "workflow_orchestration_o4-mini_group0_3/Product_Manager/tests/test_manager.py::test_cancel_task", "type": "Function", "lineno": 56}, {"nodeid": "workflow_orchestration_o4-mini_group0_3/Product_Manager/tests/test_manager.py::test_schedule_tasks", "type": "Function", "lineno": 69}]}, {"nodeid": "workflow_orchestration_o4-mini_group0_3/Data_Scientist/tests/test_task.py", "outcome": "passed", "result": [{"nodeid": "workflow_orchestration_o4-mini_group0_3/Data_Scientist/tests/test_task.py::test_task_success", "type": "Function", "lineno": 7}, {"nodeid": "workflow_orchestration_o4-mini_group0_3/Data_Scientist/tests/test_task.py::test_task_failure_with_retries", "type": "Function", "lineno": 16}, {"nodeid": "workflow_orchestration_o4-mini_group0_3/Data_Scientist/tests/test_task.py::test_task_timeout", "type": "Function", "lineno": 27}, {"nodeid": "workflow_orchestration_o4-mini_group0_3/Data_Scientist/tests/test_task.py::test_task_backoff_delay", "type": "Function", "lineno": 37}]}, {"nodeid": "workflow_orchestration_o4-mini_group0_3/Data_Scientist/tests/test_workflow.py", "outcome": "passed", "result": [{"nodeid": "workflow_orchestration_o4-mini_group0_3/Data_Scientist/tests/test_workflow.py::test_workflow_execution_order", "type": "Function", "lineno": 3}, {"nodeid": "workflow_orchestration_o4-mini_group0_3/Data_Scientist/tests/test_workflow.py::test_workflow_failure_stops_subsequent", "type": "Function", "lineno": 26}]}, {"nodeid": "workflow_orchestration_o4-mini_group0_3/Data_Scientist/tests/test_api.py", "outcome": "failed", "result": [], "longrepr": "ImportError while importing test module '/Users/celine/Research/librarybench/workflow_orchestration_o4-mini_group0_3/Data_Scientist/tests/test_api.py'.\nHint: make sure your test modules/packages have valid Python names.\nTraceback:\n../../../miniconda3/envs/library/lib/python3.13/importlib/__init__.py:88: in import_module\n    return _bootstrap._gcd_import(name[level:], package, level)\nData_Scientist/tests/test_api.py:2: in <module>\n    from Data_Scientist.api import app\nData_Scientist/api.py:1: in <module>\n    from flask import Flask, request, jsonify\nE   ModuleNotFoundError: No module named 'flask'"}, {"nodeid": "workflow_orchestration_o4-mini_group0_3/Data_Engineer/test_utils.py", "outcome": "failed", "result": [], "longrepr": "ImportError while importing test module '/Users/celine/Research/librarybench/workflow_orchestration_o4-mini_group0_3/Data_Engineer/test_utils.py'.\nHint: make sure your test modules/packages have valid Python names.\nTraceback:\n../../../miniconda3/envs/library/lib/python3.13/importlib/__init__.py:88: in import_module\n    return _bootstrap._gcd_import(name[level:], package, level)\nData_Engineer/test_utils.py:2: in <module>\n    from Data_Engineer.workflow.utils import exponential_backoff\nData_Engineer/workflow/utils.py:1: in <module>\n    from flask import request, jsonify\nE   ModuleNotFoundError: No module named 'flask'"}, {"nodeid": "workflow_orchestration_o4-mini_group0_3/Data_Engineer/test_task.py", "outcome": "failed", "result": [], "longrepr": "ImportError while importing test module '/Users/celine/Research/librarybench/workflow_orchestration_o4-mini_group0_3/Data_Engineer/test_task.py'.\nHint: make sure your test modules/packages have valid Python names.\nTraceback:\n../../../miniconda3/envs/library/lib/python3.13/importlib/__init__.py:88: in import_module\n    return _bootstrap._gcd_import(name[level:], package, level)\nData_Engineer/test_task.py:3: in <module>\n    from Data_Engineer.workflow.task import Task, TaskState\nData_Engineer/workflow/task.py:7: in <module>\n    from .utils import exponential_backoff\nData_Engineer/workflow/utils.py:1: in <module>\n    from flask import request, jsonify\nE   ModuleNotFoundError: No module named 'flask'"}, {"nodeid": "workflow_orchestration_o4-mini_group0_3/Data_Engineer/test_auth.py", "outcome": "passed", "result": [{"nodeid": "workflow_orchestration_o4-mini_group0_3/Data_Engineer/test_auth.py::test_auth_success", "type": "Function", "lineno": 3}, {"nodeid": "workflow_orchestration_o4-mini_group0_3/Data_Engineer/test_auth.py::test_auth_failure", "type": "Function", "lineno": 10}]}, {"nodeid": "workflow_orchestration_o4-mini_group0_3/Data_Engineer/test_ui.py", "outcome": "failed", "result": [], "longrepr": "ImportError while importing test module '/Users/celine/Research/librarybench/workflow_orchestration_o4-mini_group0_3/Data_Engineer/test_ui.py'.\nHint: make sure your test modules/packages have valid Python names.\nTraceback:\n../../../miniconda3/envs/library/lib/python3.13/importlib/__init__.py:88: in import_module\n    return _bootstrap._gcd_import(name[level:], package, level)\nData_Engineer/test_ui.py:3: in <module>\n    import Data_Engineer.workflow.ui as ui\nData_Engineer/workflow/ui.py:5: in <module>\n    from .manager import WorkflowManager\nData_Engineer/workflow/manager.py:7: in <module>\n    from .task import Task, TaskState\nData_Engineer/workflow/task.py:7: in <module>\n    from .utils import exponential_backoff\nData_Engineer/workflow/utils.py:1: in <module>\n    from flask import request, jsonify\nE   ModuleNotFoundError: No module named 'flask'"}, {"nodeid": "workflow_orchestration_o4-mini_group0_3/Data_Engineer/test_scheduler.py", "outcome": "passed", "result": [{"nodeid": "workflow_orchestration_o4-mini_group0_3/Data_Engineer/test_scheduler.py::test_scheduler_runs_periodically", "type": "Function", "lineno": 4}]}, {"nodeid": "workflow_orchestration_o4-mini_group0_3/Data_Engineer/test_manager.py", "outcome": "failed", "result": [], "longrepr": "ImportError while importing test module '/Users/celine/Research/librarybench/workflow_orchestration_o4-mini_group0_3/Data_Engineer/test_manager.py'.\nHint: make sure your test modules/packages have valid Python names.\nTraceback:\n../../../miniconda3/envs/library/lib/python3.13/importlib/__init__.py:88: in import_module\n    return _bootstrap._gcd_import(name[level:], package, level)\nData_Engineer/test_manager.py:2: in <module>\n    from Data_Engineer.workflow.manager import WorkflowManager\nData_Engineer/workflow/manager.py:7: in <module>\n    from .task import Task, TaskState\nData_Engineer/workflow/task.py:7: in <module>\n    from .utils import exponential_backoff\nData_Engineer/workflow/utils.py:1: in <module>\n    from flask import request, jsonify\nE   ModuleNotFoundError: No module named 'flask'"}], "tests": [{"nodeid": "workflow_orchestration_o4-mini_group0_3/Product_Manager/tests/test_manager.py::test_queue_task_success", "lineno": 4, "outcome": "failed", "keywords": ["test_queue_task_success", "test_manager.py", "tests", "Product_Manager", "workflow_orchestration_o4-mini_group0_3", "librarybench", ""], "setup": {"duration": 0.00030295799660962075, "outcome": "passed"}, "call": {"duration": 0.00016004100325517356, "outcome": "failed", "crash": {"path": "/Users/celine/Research/librarybench/workflow_orchestration_o4-mini_group0_3/Product_Manager/tests/test_manager.py", "lineno": 6, "message": "TypeError: TaskManager.__init__() got an unexpected keyword argument 'max_workers'"}, "traceback": [{"path": "Product_Manager/tests/test_manager.py", "lineno": 6, "message": "TypeError"}], "longrepr": "def test_queue_task_success():\n>       tm = TaskManager(max_workers=2)\nE       TypeError: TaskManager.__init__() got an unexpected keyword argument 'max_workers'\n\nProduct_Manager/tests/test_manager.py:6: TypeError"}, "teardown": {"duration": 0.00013166699500288814, "outcome": "passed"}}, {"nodeid": "workflow_orchestration_o4-mini_group0_3/Product_Manager/tests/test_manager.py::test_retry_failed_then_success", "lineno": 16, "outcome": "failed", "keywords": ["test_retry_failed_then_success", "test_manager.py", "tests", "Product_Manager", "workflow_orchestration_o4-mini_group0_3", "librarybench", ""], "setup": {"duration": 9.708300058264285e-05, "outcome": "passed"}, "call": {"duration": 0.00012087498907931149, "outcome": "failed", "crash": {"path": "/Users/celine/Research/librarybench/workflow_orchestration_o4-mini_group0_3/Product_Manager/tests/test_manager.py", "lineno": 18, "message": "TypeError: TaskManager.__init__() got an unexpected keyword argument 'max_workers'"}, "traceback": [{"path": "Product_Manager/tests/test_manager.py", "lineno": 18, "message": "TypeError"}], "longrepr": "def test_retry_failed_then_success():\n>       tm = TaskManager(max_workers=1)\nE       TypeError: TaskManager.__init__() got an unexpected keyword argument 'max_workers'\n\nProduct_Manager/tests/test_manager.py:18: TypeError"}, "teardown": {"duration": 0.00015741700190119445, "outcome": "passed"}}, {"nodeid": "workflow_orchestration_o4-mini_group0_3/Product_Manager/tests/test_manager.py::test_retry_exhausted_sends_alert", "lineno": 31, "outcome": "failed", "keywords": ["test_retry_exhausted_sends_alert", "test_manager.py", "tests", "Product_Manager", "workflow_orchestration_o4-mini_group0_3", "librarybench", ""], "setup": {"duration": 0.00011333399743307382, "outcome": "passed"}, "call": {"duration": 0.00013366701023187488, "outcome": "failed", "crash": {"path": "/Users/celine/Research/librarybench/workflow_orchestration_o4-mini_group0_3/Product_Manager/tests/test_manager.py", "lineno": 33, "message": "TypeError: TaskManager.__init__() got an unexpected keyword argument 'max_workers'"}, "traceback": [{"path": "Product_Manager/tests/test_manager.py", "lineno": 33, "message": "TypeError"}], "longrepr": "def test_retry_exhausted_sends_alert():\n>       tm = TaskManager(max_workers=1)\nE       TypeError: TaskManager.__init__() got an unexpected keyword argument 'max_workers'\n\nProduct_Manager/tests/test_manager.py:33: TypeError"}, "teardown": {"duration": 0.00011879099474754184, "outcome": "passed"}}, {"nodeid": "workflow_orchestration_o4-mini_group0_3/Product_Manager/tests/test_manager.py::test_timeout", "lineno": 45, "outcome": "failed", "keywords": ["test_timeout", "test_manager.py", "tests", "Product_Manager", "workflow_orchestration_o4-mini_group0_3", "librarybench", ""], "setup": {"duration": 9.620899800211191e-05, "outcome": "passed"}, "call": {"duration": 0.00011829199502244592, "outcome": "failed", "crash": {"path": "/Users/celine/Research/librarybench/workflow_orchestration_o4-mini_group0_3/Product_Manager/tests/test_manager.py", "lineno": 47, "message": "TypeError: TaskManager.__init__() got an unexpected keyword argument 'max_workers'"}, "traceback": [{"path": "Product_Manager/tests/test_manager.py", "lineno": 47, "message": "TypeError"}], "longrepr": "def test_timeout():\n>       tm = TaskManager(max_workers=1)\nE       TypeError: TaskManager.__init__() got an unexpected keyword argument 'max_workers'\n\nProduct_Manager/tests/test_manager.py:47: TypeError"}, "teardown": {"duration": 0.00010229198960587382, "outcome": "passed"}}, {"nodeid": "workflow_orchestration_o4-mini_group0_3/Product_Manager/tests/test_manager.py::test_cancel_task", "lineno": 56, "outcome": "failed", "keywords": ["test_cancel_task", "test_manager.py", "tests", "Product_Manager", "workflow_orchestration_o4-mini_group0_3", "librarybench", ""], "setup": {"duration": 9.745800343807787e-05, "outcome": "passed"}, "call": {"duration": 0.00012116700236219913, "outcome": "failed", "crash": {"path": "/Users/celine/Research/librarybench/workflow_orchestration_o4-mini_group0_3/Product_Manager/tests/test_manager.py", "lineno": 58, "message": "TypeError: TaskManager.__init__() got an unexpected keyword argument 'max_workers'"}, "traceback": [{"path": "Product_Manager/tests/test_manager.py", "lineno": 58, "message": "TypeError"}], "longrepr": "def test_cancel_task():\n>       tm = TaskManager(max_workers=1)\nE       TypeError: TaskManager.__init__() got an unexpected keyword argument 'max_workers'\n\nProduct_Manager/tests/test_manager.py:58: TypeError"}, "teardown": {"duration": 0.0001152500044554472, "outcome": "passed"}}, {"nodeid": "workflow_orchestration_o4-mini_group0_3/Product_Manager/tests/test_manager.py::test_schedule_tasks", "lineno": 69, "outcome": "failed", "keywords": ["test_schedule_tasks", "test_manager.py", "tests", "Product_Manager", "workflow_orchestration_o4-mini_group0_3", "librarybench", ""], "setup": {"duration": 9.783299174159765e-05, "outcome": "passed"}, "call": {"duration": 0.00012170799891464412, "outcome": "failed", "crash": {"path": "/Users/celine/Research/librarybench/workflow_orchestration_o4-mini_group0_3/Product_Manager/tests/test_manager.py", "lineno": 71, "message": "TypeError: TaskManager.__init__() got an unexpected keyword argument 'max_workers'"}, "traceback": [{"path": "Product_Manager/tests/test_manager.py", "lineno": 71, "message": "TypeError"}], "longrepr": "def test_schedule_tasks():\n>       tm = TaskManager(max_workers=1)\nE       TypeError: TaskManager.__init__() got an unexpected keyword argument 'max_workers'\n\nProduct_Manager/tests/test_manager.py:71: TypeError"}, "teardown": {"duration": 0.00010720900900196284, "outcome": "passed"}}, {"nodeid": "workflow_orchestration_o4-mini_group0_3/Data_Scientist/tests/test_task.py::test_task_success", "lineno": 7, "outcome": "passed", "keywords": ["test_task_success", "test_task.py", "tests", "Data_Scientist", "workflow_orchestration_o4-mini_group0_3", "librarybench", ""], "setup": {"duration": 0.00031295900407712907, "outcome": "passed"}, "call": {"duration": 0.0006370000046445057, "outcome": "passed", "stderr": "2025-05-06 14:05:17,465 - task_manager - INFO - Task t1: attempt 1 started\n2025-05-06 14:05:17,466 - task_manager - INFO - Task t1: succeeded in 0.00s\n", "log": [{"name": "task_manager", "msg": "Task t1: attempt 1 started", "args": null, "levelname": "INFO", "levelno": 20, "pathname": "/Users/celine/Research/librarybench/workflow_orchestration_o4-mini_group0_3/Data_Scientist/task_manager.py", "filename": "task_manager.py", "module": "task_manager", "exc_info": null, "exc_text": null, "stack_info": null, "lineno": 42, "funcName": "run", "created": 1746554717.4658592, "msecs": 465.0, "relativeCreated": 422.725, "thread": 4309943680, "threadName": "MainThread", "processName": "MainProcess", "process": 6577, "taskName": null, "asctime": "2025-05-06 14:05:17,465"}, {"name": "task_manager", "msg": "Task t1: succeeded in 0.00s", "args": null, "levelname": "INFO", "levelno": 20, "pathname": "/Users/celine/Research/librarybench/workflow_orchestration_o4-mini_group0_3/Data_Scientist/task_manager.py", "filename": "task_manager.py", "module": "task_manager", "exc_info": null, "exc_text": null, "stack_info": null, "lineno": 49, "funcName": "run", "created": 1746554717.466242, "msecs": 466.0, "relativeCreated": 423.108, "thread": 4309943680, "threadName": "MainThread", "processName": "MainProcess", "process": 6577, "taskName": null, "asctime": "2025-05-06 14:05:17,466"}]}, "teardown": {"duration": 8.920900290831923e-05, "outcome": "passed"}}, {"nodeid": "workflow_orchestration_o4-mini_group0_3/Data_Scientist/tests/test_task.py::test_task_failure_with_retries", "lineno": 16, "outcome": "passed", "keywords": ["test_task_failure_with_retries", "test_task.py", "tests", "Data_Scientist", "workflow_orchestration_o4-mini_group0_3", "librarybench", ""], "setup": {"duration": 9.058299474418163e-05, "outcome": "passed"}, "call": {"duration": 0.004993249996914528, "outcome": "passed", "stderr": "2025-05-06 14:05:17,466 - task_manager - INFO - Task t2: attempt 1 started\n2025-05-06 14:05:17,470 - task_manager - ERROR - Task t2: failed in 0.00s: Traceback (most recent call last):\n  File \"/Users/celine/Research/librarybench/workflow_orchestration_o4-mini_group0_3/Data_Scientist/task_manager.py\", line 76, in target\n    res = self.func()\n  File \"/Users/celine/Research/librarybench/workflow_orchestration_o4-mini_group0_3/Data_Scientist/tests/test_task.py\", line 21, in f\n    raise ValueError(\"oops\")\nValueError: oops\n2025-05-06 14:05:17,470 - task_manager - INFO - Task t2: retrying after 0.00s\n2025-05-06 14:05:17,470 - task_manager - INFO - Task t2: attempt 2 started\n2025-05-06 14:05:17,471 - task_manager - ERROR - Task t2: failed in 0.00s: Traceback (most recent call last):\n  File \"/Users/celine/Research/librarybench/workflow_orchestration_o4-mini_group0_3/Data_Scientist/task_manager.py\", line 76, in target\n    res = self.func()\n  File \"/Users/celine/Research/librarybench/workflow_orchestration_o4-mini_group0_3/Data_Scientist/tests/test_task.py\", line 21, in f\n    raise ValueError(\"oops\")\nValueError: oops\n2025-05-06 14:05:17,471 - task_manager - INFO - Task t2: retrying after 0.00s\n2025-05-06 14:05:17,471 - task_manager - INFO - Task t2: attempt 3 started\n2025-05-06 14:05:17,471 - task_manager - ERROR - Task t2: failed in 0.00s: Traceback (most recent call last):\n  File \"/Users/celine/Research/librarybench/workflow_orchestration_o4-mini_group0_3/Data_Scientist/task_manager.py\", line 76, in target\n    res = self.func()\n  File \"/Users/celine/Research/librarybench/workflow_orchestration_o4-mini_group0_3/Data_Scientist/tests/test_task.py\", line 21, in f\n    raise ValueError(\"oops\")\nValueError: oops\n2025-05-06 14:05:17,471 - task_manager - ERROR - Task t2: exceeded max retries (2)\n", "log": [{"name": "task_manager", "msg": "Task t2: attempt 1 started", "args": null, "levelname": "INFO", "levelno": 20, "pathname": "/Users/celine/Research/librarybench/workflow_orchestration_o4-mini_group0_3/Data_Scientist/task_manager.py", "filename": "task_manager.py", "module": "task_manager", "exc_info": null, "exc_text": null, "stack_info": null, "lineno": 42, "funcName": "run", "created": 1746554717.466912, "msecs": 466.0, "relativeCreated": 423.778, "thread": 4309943680, "threadName": "MainThread", "processName": "MainProcess", "process": 6577, "taskName": null, "asctime": "2025-05-06 14:05:17,466"}, {"name": "task_manager", "msg": "Task t2: failed in 0.00s: Traceback (most recent call last):\n  File \"/Users/celine/Research/librarybench/workflow_orchestration_o4-mini_group0_3/Data_Scientist/task_manager.py\", line 76, in target\n    res = self.func()\n  File \"/Users/celine/Research/librarybench/workflow_orchestration_o4-mini_group0_3/Data_Scientist/tests/test_task.py\", line 21, in f\n    raise ValueError(\"oops\")\nValueError: oops", "args": null, "levelname": "ERROR", "levelno": 40, "pathname": "/Users/celine/Research/librarybench/workflow_orchestration_o4-mini_group0_3/Data_Scientist/task_manager.py", "filename": "task_manager.py", "module": "task_manager", "exc_info": null, "exc_text": null, "stack_info": null, "lineno": 55, "funcName": "run", "created": 1746554717.47068, "msecs": 470.0, "relativeCreated": 427.546, "thread": 4309943680, "threadName": "MainThread", "processName": "MainProcess", "process": 6577, "taskName": null, "asctime": "2025-05-06 14:05:17,470"}, {"name": "task_manager", "msg": "Task t2: retrying after 0.00s", "args": null, "levelname": "INFO", "levelno": 20, "pathname": "/Users/celine/Research/librarybench/workflow_orchestration_o4-mini_group0_3/Data_Scientist/task_manager.py", "filename": "task_manager.py", "module": "task_manager", "exc_info": null, "exc_text": null, "stack_info": null, "lineno": 62, "funcName": "run", "created": 1746554717.470779, "msecs": 470.0, "relativeCreated": 427.645, "thread": 4309943680, "threadName": "MainThread", "processName": "MainProcess", "process": 6577, "taskName": null, "asctime": "2025-05-06 14:05:17,470"}, {"name": "task_manager", "msg": "Task t2: attempt 2 started", "args": null, "levelname": "INFO", "levelno": 20, "pathname": "/Users/celine/Research/librarybench/workflow_orchestration_o4-mini_group0_3/Data_Scientist/task_manager.py", "filename": "task_manager.py", "module": "task_manager", "exc_info": null, "exc_text": null, "stack_info": null, "lineno": 42, "funcName": "run", "created": 1746554717.470834, "msecs": 470.0, "relativeCreated": 427.7, "thread": 4309943680, "threadName": "MainThread", "processName": "MainProcess", "process": 6577, "taskName": null, "asctime": "2025-05-06 14:05:17,470"}, {"name": "task_manager", "msg": "Task t2: failed in 0.00s: Traceback (most recent call last):\n  File \"/Users/celine/Research/librarybench/workflow_orchestration_o4-mini_group0_3/Data_Scientist/task_manager.py\", line 76, in target\n    res = self.func()\n  File \"/Users/celine/Research/librarybench/workflow_orchestration_o4-mini_group0_3/Data_Scientist/tests/test_task.py\", line 21, in f\n    raise ValueError(\"oops\")\nValueError: oops", "args": null, "levelname": "ERROR", "levelno": 40, "pathname": "/Users/celine/Research/librarybench/workflow_orchestration_o4-mini_group0_3/Data_Scientist/task_manager.py", "filename": "task_manager.py", "module": "task_manager", "exc_info": null, "exc_text": null, "stack_info": null, "lineno": 55, "funcName": "run", "created": 1746554717.4711921, "msecs": 471.0, "relativeCreated": 428.058, "thread": 4309943680, "threadName": "MainThread", "processName": "MainProcess", "process": 6577, "taskName": null, "asctime": "2025-05-06 14:05:17,471"}, {"name": "task_manager", "msg": "Task t2: retrying after 0.00s", "args": null, "levelname": "INFO", "levelno": 20, "pathname": "/Users/celine/Research/librarybench/workflow_orchestration_o4-mini_group0_3/Data_Scientist/task_manager.py", "filename": "task_manager.py", "module": "task_manager", "exc_info": null, "exc_text": null, "stack_info": null, "lineno": 62, "funcName": "run", "created": 1746554717.471267, "msecs": 471.0, "relativeCreated": 428.133, "thread": 4309943680, "threadName": "MainThread", "processName": "MainProcess", "process": 6577, "taskName": null, "asctime": "2025-05-06 14:05:17,471"}, {"name": "task_manager", "msg": "Task t2: attempt 3 started", "args": null, "levelname": "INFO", "levelno": 20, "pathname": "/Users/celine/Research/librarybench/workflow_orchestration_o4-mini_group0_3/Data_Scientist/task_manager.py", "filename": "task_manager.py", "module": "task_manager", "exc_info": null, "exc_text": null, "stack_info": null, "lineno": 42, "funcName": "run", "created": 1746554717.471317, "msecs": 471.0, "relativeCreated": 428.183, "thread": 4309943680, "threadName": "MainThread", "processName": "MainProcess", "process": 6577, "taskName": null, "asctime": "2025-05-06 14:05:17,471"}, {"name": "task_manager", "msg": "Task t2: failed in 0.00s: Traceback (most recent call last):\n  File \"/Users/celine/Research/librarybench/workflow_orchestration_o4-mini_group0_3/Data_Scientist/task_manager.py\", line 76, in target\n    res = self.func()\n  File \"/Users/celine/Research/librarybench/workflow_orchestration_o4-mini_group0_3/Data_Scientist/tests/test_task.py\", line 21, in f\n    raise ValueError(\"oops\")\nValueError: oops", "args": null, "levelname": "ERROR", "levelno": 40, "pathname": "/Users/celine/Research/librarybench/workflow_orchestration_o4-mini_group0_3/Data_Scientist/task_manager.py", "filename": "task_manager.py", "module": "task_manager", "exc_info": null, "exc_text": null, "stack_info": null, "lineno": 55, "funcName": "run", "created": 1746554717.471603, "msecs": 471.0, "relativeCreated": 428.469, "thread": 4309943680, "threadName": "MainThread", "processName": "MainProcess", "process": 6577, "taskName": null, "asctime": "2025-05-06 14:05:17,471"}, {"name": "task_manager", "msg": "Task t2: exceeded max retries (2)", "args": null, "levelname": "ERROR", "levelno": 40, "pathname": "/Users/celine/Research/librarybench/workflow_orchestration_o4-mini_group0_3/Data_Scientist/task_manager.py", "filename": "task_manager.py", "module": "task_manager", "exc_info": null, "exc_text": null, "stack_info": null, "lineno": 58, "funcName": "run", "created": 1746554717.471658, "msecs": 471.0, "relativeCreated": 428.524, "thread": 4309943680, "threadName": "MainThread", "processName": "MainProcess", "process": 6577, "taskName": null, "asctime": "2025-05-06 14:05:17,471"}]}, "teardown": {"duration": 0.00010341600864194334, "outcome": "passed"}}, {"nodeid": "workflow_orchestration_o4-mini_group0_3/Data_Scientist/tests/test_task.py::test_task_timeout", "lineno": 27, "outcome": "passed", "keywords": ["test_task_timeout", "test_task.py", "tests", "Data_Scientist", "workflow_orchestration_o4-mini_group0_3", "librarybench", ""], "setup": {"duration": 9.145800140686333e-05, "outcome": "passed"}, "call": {"duration": 1.0046735840005567, "outcome": "passed", "stderr": "2025-05-06 14:05:17,472 - task_manager - INFO - Task t3: attempt 1 started\n2025-05-06 14:05:18,475 - task_manager - ERROR - Task t3: failed in 1.00s: Timeout after 1s\n2025-05-06 14:05:18,476 - task_manager - ERROR - Task t3: exceeded max retries (0)\n", "log": [{"name": "task_manager", "msg": "Task t3: attempt 1 started", "args": null, "levelname": "INFO", "levelno": 20, "pathname": "/Users/celine/Research/librarybench/workflow_orchestration_o4-mini_group0_3/Data_Scientist/task_manager.py", "filename": "task_manager.py", "module": "task_manager", "exc_info": null, "exc_text": null, "stack_info": null, "lineno": 42, "funcName": "run", "created": 1746554717.47237, "msecs": 472.0, "relativeCreated": 429.236, "thread": 4309943680, "threadName": "MainThread", "processName": "MainProcess", "process": 6577, "taskName": null, "asctime": "2025-05-06 14:05:17,472"}, {"name": "task_manager", "msg": "Task t3: failed in 1.00s: Timeout after 1s", "args": null, "levelname": "ERROR", "levelno": 40, "pathname": "/Users/celine/Research/librarybench/workflow_orchestration_o4-mini_group0_3/Data_Scientist/task_manager.py", "filename": "task_manager.py", "module": "task_manager", "exc_info": null, "exc_text": null, "stack_info": null, "lineno": 55, "funcName": "run", "created": 1746554718.475743, "msecs": 475.0, "relativeCreated": 1432.609, "thread": 4309943680, "threadName": "MainThread", "processName": "MainProcess", "process": 6577, "taskName": null, "asctime": "2025-05-06 14:05:18,475"}, {"name": "task_manager", "msg": "Task t3: exceeded max retries (0)", "args": null, "levelname": "ERROR", "levelno": 40, "pathname": "/Users/celine/Research/librarybench/workflow_orchestration_o4-mini_group0_3/Data_Scientist/task_manager.py", "filename": "task_manager.py", "module": "task_manager", "exc_info": null, "exc_text": null, "stack_info": null, "lineno": 58, "funcName": "run", "created": 1746554718.476265, "msecs": 476.0, "relativeCreated": 1433.131, "thread": 4309943680, "threadName": "MainThread", "processName": "MainProcess", "process": 6577, "taskName": null, "asctime": "2025-05-06 14:05:18,476"}]}, "teardown": {"duration": 0.00045375000627245754, "outcome": "passed"}}, {"nodeid": "workflow_orchestration_o4-mini_group0_3/Data_Scientist/tests/test_task.py::test_task_backoff_delay", "lineno": 37, "outcome": "passed", "keywords": ["test_task_backoff_delay", "test_task.py", "tests", "Data_Scientist", "workflow_orchestration_o4-mini_group0_3", "librarybench", ""], "setup": {"duration": 0.00039312499575316906, "outcome": "passed"}, "call": {"duration": 1.006089709000662, "outcome": "passed", "stderr": "2025-05-06 14:05:18,479 - task_manager - INFO - Task t4: attempt 1 started\n2025-05-06 14:05:18,480 - task_manager - ERROR - Task t4: failed in 0.00s: Traceback (most recent call last):\n  File \"/Users/celine/Research/librarybench/workflow_orchestration_o4-mini_group0_3/Data_Scientist/task_manager.py\", line 76, in target\n    res = self.func()\n  File \"/Users/celine/Research/librarybench/workflow_orchestration_o4-mini_group0_3/Data_Scientist/tests/test_task.py\", line 43, in f\n    raise RuntimeError(\"fail\")\nRuntimeError: fail\n2025-05-06 14:05:18,481 - task_manager - INFO - Task t4: retrying after 1.00s\n2025-05-06 14:05:19,483 - task_manager - INFO - Task t4: attempt 2 started\n2025-05-06 14:05:19,484 - task_manager - INFO - Task t4: succeeded in 0.00s\n", "log": [{"name": "task_manager", "msg": "Task t4: attempt 1 started", "args": null, "levelname": "INFO", "levelno": 20, "pathname": "/Users/celine/Research/librarybench/workflow_orchestration_o4-mini_group0_3/Data_Scientist/task_manager.py", "filename": "task_manager.py", "module": "task_manager", "exc_info": null, "exc_text": null, "stack_info": null, "lineno": 42, "funcName": "run", "created": 1746554718.4792, "msecs": 479.0, "relativeCreated": 1436.066, "thread": 4309943680, "threadName": "MainThread", "processName": "MainProcess", "process": 6577, "taskName": null, "asctime": "2025-05-06 14:05:18,479"}, {"name": "task_manager", "msg": "Task t4: failed in 0.00s: Traceback (most recent call last):\n  File \"/Users/celine/Research/librarybench/workflow_orchestration_o4-mini_group0_3/Data_Scientist/task_manager.py\", line 76, in target\n    res = self.func()\n  File \"/Users/celine/Research/librarybench/workflow_orchestration_o4-mini_group0_3/Data_Scientist/tests/test_task.py\", line 43, in f\n    raise RuntimeError(\"fail\")\nRuntimeError: fail", "args": null, "levelname": "ERROR", "levelno": 40, "pathname": "/Users/celine/Research/librarybench/workflow_orchestration_o4-mini_group0_3/Data_Scientist/task_manager.py", "filename": "task_manager.py", "module": "task_manager", "exc_info": null, "exc_text": null, "stack_info": null, "lineno": 55, "funcName": "run", "created": 1746554718.480961, "msecs": 480.0, "relativeCreated": 1437.827, "thread": 4309943680, "threadName": "MainThread", "processName": "MainProcess", "process": 6577, "taskName": null, "asctime": "2025-05-06 14:05:18,480"}, {"name": "task_manager", "msg": "Task t4: retrying after 1.00s", "args": null, "levelname": "INFO", "levelno": 20, "pathname": "/Users/celine/Research/librarybench/workflow_orchestration_o4-mini_group0_3/Data_Scientist/task_manager.py", "filename": "task_manager.py", "module": "task_manager", "exc_info": null, "exc_text": null, "stack_info": null, "lineno": 62, "funcName": "run", "created": 1746554718.481218, "msecs": 481.0, "relativeCreated": 1438.084, "thread": 4309943680, "threadName": "MainThread", "processName": "MainProcess", "process": 6577, "taskName": null, "asctime": "2025-05-06 14:05:18,481"}, {"name": "task_manager", "msg": "Task t4: attempt 2 started", "args": null, "levelname": "INFO", "levelno": 20, "pathname": "/Users/celine/Research/librarybench/workflow_orchestration_o4-mini_group0_3/Data_Scientist/task_manager.py", "filename": "task_manager.py", "module": "task_manager", "exc_info": null, "exc_text": null, "stack_info": null, "lineno": 42, "funcName": "run", "created": 1746554719.483548, "msecs": 483.0, "relativeCreated": 2440.414, "thread": 4309943680, "threadName": "MainThread", "processName": "MainProcess", "process": 6577, "taskName": null, "asctime": "2025-05-06 14:05:19,483"}, {"name": "task_manager", "msg": "Task t4: succeeded in 0.00s", "args": null, "levelname": "INFO", "levelno": 20, "pathname": "/Users/celine/Research/librarybench/workflow_orchestration_o4-mini_group0_3/Data_Scientist/task_manager.py", "filename": "task_manager.py", "module": "task_manager", "exc_info": null, "exc_text": null, "stack_info": null, "lineno": 49, "funcName": "run", "created": 1746554719.484319, "msecs": 484.0, "relativeCreated": 2441.185, "thread": 4309943680, "threadName": "MainThread", "processName": "MainProcess", "process": 6577, "taskName": null, "asctime": "2025-05-06 14:05:19,484"}]}, "teardown": {"duration": 0.0003754170029424131, "outcome": "passed"}}, {"nodeid": "workflow_orchestration_o4-mini_group0_3/Data_Scientist/tests/test_workflow.py::test_workflow_execution_order", "lineno": 3, "outcome": "passed", "keywords": ["test_workflow_execution_order", "test_workflow.py", "tests", "Data_Scientist", "workflow_orchestration_o4-mini_group0_3", "librarybench", ""], "setup": {"duration": 0.0004072500014444813, "outcome": "passed"}, "call": {"duration": 0.0029809590050717816, "outcome": "passed", "stderr": "2025-05-06 14:05:19,487 - task_manager - INFO - Registered workflow 'wf1' (ID: fd25403d-a24a-4a28-aeb8-6e848c8e03c1)\n2025-05-06 14:05:19,488 - task_manager - INFO - Added task 'a' to workflow 'fd25403d-a24a-4a28-aeb8-6e848c8e03c1'\n2025-05-06 14:05:19,488 - task_manager - INFO - Added task 'b' to workflow 'fd25403d-a24a-4a28-aeb8-6e848c8e03c1'\n2025-05-06 14:05:19,488 - task_manager - INFO - Added task 'c' to workflow 'fd25403d-a24a-4a28-aeb8-6e848c8e03c1'\n2025-05-06 14:05:19,488 - task_manager - INFO - Starting workflow 'fd25403d-a24a-4a28-aeb8-6e848c8e03c1' (v1)\n2025-05-06 14:05:19,488 - task_manager - INFO - Task a: attempt 1 started\n2025-05-06 14:05:19,488 - task_manager - INFO - Task a: succeeded in 0.00s\n2025-05-06 14:05:19,489 - task_manager - INFO - Task b: attempt 1 started\n2025-05-06 14:05:19,489 - task_manager - INFO - Task b: succeeded in 0.00s\n2025-05-06 14:05:19,489 - task_manager - INFO - Task c: attempt 1 started\n2025-05-06 14:05:19,489 - task_manager - INFO - Task c: succeeded in 0.00s\n2025-05-06 14:05:19,489 - task_manager - INFO - Workflow 'fd25403d-a24a-4a28-aeb8-6e848c8e03c1' completed successfully\n", "log": [{"name": "task_manager", "msg": "Registered workflow 'wf1' (ID: fd25403d-a24a-4a28-aeb8-6e848c8e03c1)", "args": null, "levelname": "INFO", "levelno": 20, "pathname": "/Users/celine/Research/librarybench/workflow_orchestration_o4-mini_group0_3/Data_Scientist/task_manager.py", "filename": "task_manager.py", "module": "task_manager", "exc_info": null, "exc_text": null, "stack_info": null, "lineno": 127, "funcName": "register_workflow", "created": 1746554719.487798, "msecs": 487.0, "relativeCreated": 2444.664, "thread": 4309943680, "threadName": "MainThread", "processName": "MainProcess", "process": 6577, "taskName": null, "asctime": "2025-05-06 14:05:19,487"}, {"name": "task_manager", "msg": "Added task 'a' to workflow 'fd25403d-a24a-4a28-aeb8-6e848c8e03c1'", "args": null, "levelname": "INFO", "levelno": 20, "pathname": "/Users/celine/Research/librarybench/workflow_orchestration_o4-mini_group0_3/Data_Scientist/task_manager.py", "filename": "task_manager.py", "module": "task_manager", "exc_info": null, "exc_text": null, "stack_info": null, "lineno": 151, "funcName": "add_task_to_workflow", "created": 1746554719.4881752, "msecs": 488.0, "relativeCreated": 2445.041, "thread": 4309943680, "threadName": "MainThread", "processName": "MainProcess", "process": 6577, "taskName": null, "asctime": "2025-05-06 14:05:19,488"}, {"name": "task_manager", "msg": "Added task 'b' to workflow 'fd25403d-a24a-4a28-aeb8-6e848c8e03c1'", "args": null, "levelname": "INFO", "levelno": 20, "pathname": "/Users/celine/Research/librarybench/workflow_orchestration_o4-mini_group0_3/Data_Scientist/task_manager.py", "filename": "task_manager.py", "module": "task_manager", "exc_info": null, "exc_text": null, "stack_info": null, "lineno": 151, "funcName": "add_task_to_workflow", "created": 1746554719.488283, "msecs": 488.0, "relativeCreated": 2445.149, "thread": 4309943680, "threadName": "MainThread", "processName": "MainProcess", "process": 6577, "taskName": null, "asctime": "2025-05-06 14:05:19,488"}, {"name": "task_manager", "msg": "Added task 'c' to workflow 'fd25403d-a24a-4a28-aeb8-6e848c8e03c1'", "args": null, "levelname": "INFO", "levelno": 20, "pathname": "/Users/celine/Research/librarybench/workflow_orchestration_o4-mini_group0_3/Data_Scientist/task_manager.py", "filename": "task_manager.py", "module": "task_manager", "exc_info": null, "exc_text": null, "stack_info": null, "lineno": 151, "funcName": "add_task_to_workflow", "created": 1746554719.488371, "msecs": 488.0, "relativeCreated": 2445.237, "thread": 4309943680, "threadName": "MainThread", "processName": "MainProcess", "process": 6577, "taskName": null, "asctime": "2025-05-06 14:05:19,488"}, {"name": "task_manager", "msg": "Starting workflow 'fd25403d-a24a-4a28-aeb8-6e848c8e03c1' (v1)", "args": null, "levelname": "INFO", "levelno": 20, "pathname": "/Users/celine/Research/librarybench/workflow_orchestration_o4-mini_group0_3/Data_Scientist/task_manager.py", "filename": "task_manager.py", "module": "task_manager", "exc_info": null, "exc_text": null, "stack_info": null, "lineno": 165, "funcName": "run_workflow", "created": 1746554719.488462, "msecs": 488.0, "relativeCreated": 2445.328, "thread": 4309943680, "threadName": "MainThread", "processName": "MainProcess", "process": 6577, "taskName": null, "asctime": "2025-05-06 14:05:19,488"}, {"name": "task_manager", "msg": "Task a: attempt 1 started", "args": null, "levelname": "INFO", "levelno": 20, "pathname": "/Users/celine/Research/librarybench/workflow_orchestration_o4-mini_group0_3/Data_Scientist/task_manager.py", "filename": "task_manager.py", "module": "task_manager", "exc_info": null, "exc_text": null, "stack_info": null, "lineno": 42, "funcName": "run", "created": 1746554719.488588, "msecs": 488.0, "relativeCreated": 2445.454, "thread": 4309943680, "threadName": "MainThread", "processName": "MainProcess", "process": 6577, "taskName": null, "asctime": "2025-05-06 14:05:19,488"}, {"name": "task_manager", "msg": "Task a: succeeded in 0.00s", "args": null, "levelname": "INFO", "levelno": 20, "pathname": "/Users/celine/Research/librarybench/workflow_orchestration_o4-mini_group0_3/Data_Scientist/task_manager.py", "filename": "task_manager.py", "module": "task_manager", "exc_info": null, "exc_text": null, "stack_info": null, "lineno": 49, "funcName": "run", "created": 1746554719.488946, "msecs": 488.0, "relativeCreated": 2445.812, "thread": 4309943680, "threadName": "MainThread", "processName": "MainProcess", "process": 6577, "taskName": null, "asctime": "2025-05-06 14:05:19,488"}, {"name": "task_manager", "msg": "Task b: attempt 1 started", "args": null, "levelname": "INFO", "levelno": 20, "pathname": "/Users/celine/Research/librarybench/workflow_orchestration_o4-mini_group0_3/Data_Scientist/task_manager.py", "filename": "task_manager.py", "module": "task_manager", "exc_info": null, "exc_text": null, "stack_info": null, "lineno": 42, "funcName": "run", "created": 1746554719.4891, "msecs": 489.0, "relativeCreated": 2445.966, "thread": 4309943680, "threadName": "MainThread", "processName": "MainProcess", "process": 6577, "taskName": null, "asctime": "2025-05-06 14:05:19,489"}, {"name": "task_manager", "msg": "Task b: succeeded in 0.00s", "args": null, "levelname": "INFO", "levelno": 20, "pathname": "/Users/celine/Research/librarybench/workflow_orchestration_o4-mini_group0_3/Data_Scientist/task_manager.py", "filename": "task_manager.py", "module": "task_manager", "exc_info": null, "exc_text": null, "stack_info": null, "lineno": 49, "funcName": "run", "created": 1746554719.489326, "msecs": 489.0, "relativeCreated": 2446.192, "thread": 4309943680, "threadName": "MainThread", "processName": "MainProcess", "process": 6577, "taskName": null, "asctime": "2025-05-06 14:05:19,489"}, {"name": "task_manager", "msg": "Task c: attempt 1 started", "args": null, "levelname": "INFO", "levelno": 20, "pathname": "/Users/celine/Research/librarybench/workflow_orchestration_o4-mini_group0_3/Data_Scientist/task_manager.py", "filename": "task_manager.py", "module": "task_manager", "exc_info": null, "exc_text": null, "stack_info": null, "lineno": 42, "funcName": "run", "created": 1746554719.489439, "msecs": 489.0, "relativeCreated": 2446.305, "thread": 4309943680, "threadName": "MainThread", "processName": "MainProcess", "process": 6577, "taskName": null, "asctime": "2025-05-06 14:05:19,489"}, {"name": "task_manager", "msg": "Task c: succeeded in 0.00s", "args": null, "levelname": "INFO", "levelno": 20, "pathname": "/Users/celine/Research/librarybench/workflow_orchestration_o4-mini_group0_3/Data_Scientist/task_manager.py", "filename": "task_manager.py", "module": "task_manager", "exc_info": null, "exc_text": null, "stack_info": null, "lineno": 49, "funcName": "run", "created": 1746554719.489631, "msecs": 489.0, "relativeCreated": 2446.497, "thread": 4309943680, "threadName": "MainThread", "processName": "MainProcess", "process": 6577, "taskName": null, "asctime": "2025-05-06 14:05:19,489"}, {"name": "task_manager", "msg": "Workflow 'fd25403d-a24a-4a28-aeb8-6e848c8e03c1' completed successfully", "args": null, "levelname": "INFO", "levelno": 20, "pathname": "/Users/celine/Research/librarybench/workflow_orchestration_o4-mini_group0_3/Data_Scientist/task_manager.py", "filename": "task_manager.py", "module": "task_manager", "exc_info": null, "exc_text": null, "stack_info": null, "lineno": 189, "funcName": "run_workflow", "created": 1746554719.489732, "msecs": 489.0, "relativeCreated": 2446.598, "thread": 4309943680, "threadName": "MainThread", "processName": "MainProcess", "process": 6577, "taskName": null, "asctime": "2025-05-06 14:05:19,489"}]}, "teardown": {"duration": 0.000452958993264474, "outcome": "passed"}}, {"nodeid": "workflow_orchestration_o4-mini_group0_3/Data_Scientist/tests/test_workflow.py::test_workflow_failure_stops_subsequent", "lineno": 26, "outcome": "passed", "keywords": ["test_workflow_failure_stops_subsequent", "test_workflow.py", "tests", "Data_Scientist", "workflow_orchestration_o4-mini_group0_3", "librarybench", ""], "setup": {"duration": 0.00024575000861659646, "outcome": "passed"}, "call": {"duration": 0.005543874998693354, "outcome": "passed", "stderr": "2025-05-06 14:05:19,492 - task_manager - INFO - Registered workflow 'wf2' (ID: d117b36d-c602-4eee-8ca6-ed04e9b146d7)\n2025-05-06 14:05:19,492 - task_manager - INFO - Added task 'a' to workflow 'd117b36d-c602-4eee-8ca6-ed04e9b146d7'\n2025-05-06 14:05:19,492 - task_manager - INFO - Added task 'b' to workflow 'd117b36d-c602-4eee-8ca6-ed04e9b146d7'\n2025-05-06 14:05:19,492 - task_manager - INFO - Added task 'c' to workflow 'd117b36d-c602-4eee-8ca6-ed04e9b146d7'\n2025-05-06 14:05:19,492 - task_manager - INFO - Starting workflow 'd117b36d-c602-4eee-8ca6-ed04e9b146d7' (v1)\n2025-05-06 14:05:19,492 - task_manager - INFO - Task a: attempt 1 started\n2025-05-06 14:05:19,493 - task_manager - INFO - Task a: succeeded in 0.00s\n2025-05-06 14:05:19,493 - task_manager - INFO - Task b: attempt 1 started\n2025-05-06 14:05:19,496 - task_manager - ERROR - Task b: failed in 0.00s: Traceback (most recent call last):\n  File \"/Users/celine/Research/librarybench/workflow_orchestration_o4-mini_group0_3/Data_Scientist/task_manager.py\", line 76, in target\n    res = self.func()\n  File \"/Users/celine/Research/librarybench/workflow_orchestration_o4-mini_group0_3/Data_Scientist/tests/test_workflow.py\", line 36, in b\n    raise RuntimeError(\"fail\")\nRuntimeError: fail\n2025-05-06 14:05:19,496 - task_manager - ERROR - Task b: exceeded max retries (0)\n2025-05-06 14:05:19,496 - task_manager - ERROR - Workflow 'd117b36d-c602-4eee-8ca6-ed04e9b146d7' failed at task 'b': Task b failed after 1 attempts: Traceback (most recent call last):\n  File \"/Users/celine/Research/librarybench/workflow_orchestration_o4-mini_group0_3/Data_Scientist/task_manager.py\", line 76, in target\n    res = self.func()\n  File \"/Users/celine/Research/librarybench/workflow_orchestration_o4-mini_group0_3/Data_Scientist/tests/test_workflow.py\", line 36, in b\n    raise RuntimeError(\"fail\")\nRuntimeError: fail\n\n", "log": [{"name": "task_manager", "msg": "Registered workflow 'wf2' (ID: d117b36d-c602-4eee-8ca6-ed04e9b146d7)", "args": null, "levelname": "INFO", "levelno": 20, "pathname": "/Users/celine/Research/librarybench/workflow_orchestration_o4-mini_group0_3/Data_Scientist/task_manager.py", "filename": "task_manager.py", "module": "task_manager", "exc_info": null, "exc_text": null, "stack_info": null, "lineno": 127, "funcName": "register_workflow", "created": 1746554719.4923148, "msecs": 492.0, "relativeCreated": 2449.181, "thread": 4309943680, "threadName": "MainThread", "processName": "MainProcess", "process": 6577, "taskName": null, "asctime": "2025-05-06 14:05:19,492"}, {"name": "task_manager", "msg": "Added task 'a' to workflow 'd117b36d-c602-4eee-8ca6-ed04e9b146d7'", "args": null, "levelname": "INFO", "levelno": 20, "pathname": "/Users/celine/Research/librarybench/workflow_orchestration_o4-mini_group0_3/Data_Scientist/task_manager.py", "filename": "task_manager.py", "module": "task_manager", "exc_info": null, "exc_text": null, "stack_info": null, "lineno": 151, "funcName": "add_task_to_workflow", "created": 1746554719.492576, "msecs": 492.0, "relativeCreated": 2449.442, "thread": 4309943680, "threadName": "MainThread", "processName": "MainProcess", "process": 6577, "taskName": null, "asctime": "2025-05-06 14:05:19,492"}, {"name": "task_manager", "msg": "Added task 'b' to workflow 'd117b36d-c602-4eee-8ca6-ed04e9b146d7'", "args": null, "levelname": "INFO", "levelno": 20, "pathname": "/Users/celine/Research/librarybench/workflow_orchestration_o4-mini_group0_3/Data_Scientist/task_manager.py", "filename": "task_manager.py", "module": "task_manager", "exc_info": null, "exc_text": null, "stack_info": null, "lineno": 151, "funcName": "add_task_to_workflow", "created": 1746554719.492678, "msecs": 492.0, "relativeCreated": 2449.544, "thread": 4309943680, "threadName": "MainThread", "processName": "MainProcess", "process": 6577, "taskName": null, "asctime": "2025-05-06 14:05:19,492"}, {"name": "task_manager", "msg": "Added task 'c' to workflow 'd117b36d-c602-4eee-8ca6-ed04e9b146d7'", "args": null, "levelname": "INFO", "levelno": 20, "pathname": "/Users/celine/Research/librarybench/workflow_orchestration_o4-mini_group0_3/Data_Scientist/task_manager.py", "filename": "task_manager.py", "module": "task_manager", "exc_info": null, "exc_text": null, "stack_info": null, "lineno": 151, "funcName": "add_task_to_workflow", "created": 1746554719.4927628, "msecs": 492.0, "relativeCreated": 2449.629, "thread": 4309943680, "threadName": "MainThread", "processName": "MainProcess", "process": 6577, "taskName": null, "asctime": "2025-05-06 14:05:19,492"}, {"name": "task_manager", "msg": "Starting workflow 'd117b36d-c602-4eee-8ca6-ed04e9b146d7' (v1)", "args": null, "levelname": "INFO", "levelno": 20, "pathname": "/Users/celine/Research/librarybench/workflow_orchestration_o4-mini_group0_3/Data_Scientist/task_manager.py", "filename": "task_manager.py", "module": "task_manager", "exc_info": null, "exc_text": null, "stack_info": null, "lineno": 165, "funcName": "run_workflow", "created": 1746554719.4928472, "msecs": 492.0, "relativeCreated": 2449.713, "thread": 4309943680, "threadName": "MainThread", "processName": "MainProcess", "process": 6577, "taskName": null, "asctime": "2025-05-06 14:05:19,492"}, {"name": "task_manager", "msg": "Task a: attempt 1 started", "args": null, "levelname": "INFO", "levelno": 20, "pathname": "/Users/celine/Research/librarybench/workflow_orchestration_o4-mini_group0_3/Data_Scientist/task_manager.py", "filename": "task_manager.py", "module": "task_manager", "exc_info": null, "exc_text": null, "stack_info": null, "lineno": 42, "funcName": "run", "created": 1746554719.492955, "msecs": 492.0, "relativeCreated": 2449.821, "thread": 4309943680, "threadName": "MainThread", "processName": "MainProcess", "process": 6577, "taskName": null, "asctime": "2025-05-06 14:05:19,492"}, {"name": "task_manager", "msg": "Task a: succeeded in 0.00s", "args": null, "levelname": "INFO", "levelno": 20, "pathname": "/Users/celine/Research/librarybench/workflow_orchestration_o4-mini_group0_3/Data_Scientist/task_manager.py", "filename": "task_manager.py", "module": "task_manager", "exc_info": null, "exc_text": null, "stack_info": null, "lineno": 49, "funcName": "run", "created": 1746554719.493313, "msecs": 493.0, "relativeCreated": 2450.179, "thread": 4309943680, "threadName": "MainThread", "processName": "MainProcess", "process": 6577, "taskName": null, "asctime": "2025-05-06 14:05:19,493"}, {"name": "task_manager", "msg": "Task b: attempt 1 started", "args": null, "levelname": "INFO", "levelno": 20, "pathname": "/Users/celine/Research/librarybench/workflow_orchestration_o4-mini_group0_3/Data_Scientist/task_manager.py", "filename": "task_manager.py", "module": "task_manager", "exc_info": null, "exc_text": null, "stack_info": null, "lineno": 42, "funcName": "run", "created": 1746554719.493471, "msecs": 493.0, "relativeCreated": 2450.337, "thread": 4309943680, "threadName": "MainThread", "processName": "MainProcess", "process": 6577, "taskName": null, "asctime": "2025-05-06 14:05:19,493"}, {"name": "task_manager", "msg": "Task b: failed in 0.00s: Traceback (most recent call last):\n  File \"/Users/celine/Research/librarybench/workflow_orchestration_o4-mini_group0_3/Data_Scientist/task_manager.py\", line 76, in target\n    res = self.func()\n  File \"/Users/celine/Research/librarybench/workflow_orchestration_o4-mini_group0_3/Data_Scientist/tests/test_workflow.py\", line 36, in b\n    raise RuntimeError(\"fail\")\nRuntimeError: fail", "args": null, "levelname": "ERROR", "levelno": 40, "pathname": "/Users/celine/Research/librarybench/workflow_orchestration_o4-mini_group0_3/Data_Scientist/task_manager.py", "filename": "task_manager.py", "module": "task_manager", "exc_info": null, "exc_text": null, "stack_info": null, "lineno": 55, "funcName": "run", "created": 1746554719.496437, "msecs": 496.0, "relativeCreated": 2453.303, "thread": 4309943680, "threadName": "MainThread", "processName": "MainProcess", "process": 6577, "taskName": null, "asctime": "2025-05-06 14:05:19,496"}, {"name": "task_manager", "msg": "Task b: exceeded max retries (0)", "args": null, "levelname": "ERROR", "levelno": 40, "pathname": "/Users/celine/Research/librarybench/workflow_orchestration_o4-mini_group0_3/Data_Scientist/task_manager.py", "filename": "task_manager.py", "module": "task_manager", "exc_info": null, "exc_text": null, "stack_info": null, "lineno": 58, "funcName": "run", "created": 1746554719.496696, "msecs": 496.0, "relativeCreated": 2453.562, "thread": 4309943680, "threadName": "MainThread", "processName": "MainProcess", "process": 6577, "taskName": null, "asctime": "2025-05-06 14:05:19,496"}, {"name": "task_manager", "msg": "Workflow 'd117b36d-c602-4eee-8ca6-ed04e9b146d7' failed at task 'b': Task b failed after 1 attempts: Traceback (most recent call last):\n  File \"/Users/celine/Research/librarybench/workflow_orchestration_o4-mini_group0_3/Data_Scientist/task_manager.py\", line 76, in target\n    res = self.func()\n  File \"/Users/celine/Research/librarybench/workflow_orchestration_o4-mini_group0_3/Data_Scientist/tests/test_workflow.py\", line 36, in b\n    raise RuntimeError(\"fail\")\nRuntimeError: fail\n", "args": null, "levelname": "ERROR", "levelno": 40, "pathname": "/Users/celine/Research/librarybench/workflow_orchestration_o4-mini_group0_3/Data_Scientist/task_manager.py", "filename": "task_manager.py", "module": "task_manager", "exc_info": null, "exc_text": null, "stack_info": null, "lineno": 183, "funcName": "run_workflow", "created": 1746554719.496823, "msecs": 496.0, "relativeCreated": 2453.689, "thread": 4309943680, "threadName": "MainThread", "processName": "MainProcess", "process": 6577, "taskName": null, "asctime": "2025-05-06 14:05:19,496"}]}, "teardown": {"duration": 0.0002842499961843714, "outcome": "passed"}}, {"nodeid": "workflow_orchestration_o4-mini_group0_3/Data_Engineer/test_auth.py::test_auth_success", "lineno": 3, "outcome": "passed", "keywords": ["test_auth_success", "test_auth.py", "Data_Engineer", "workflow_orchestration_o4-mini_group0_3", "librarybench", ""], "setup": {"duration": 0.0007896249881014228, "outcome": "passed"}, "call": {"duration": 0.0002852500037988648, "outcome": "passed"}, "teardown": {"duration": 0.0003297500079497695, "outcome": "passed"}}, {"nodeid": "workflow_orchestration_o4-mini_group0_3/Data_Engineer/test_auth.py::test_auth_failure", "lineno": 10, "outcome": "passed", "keywords": ["test_auth_failure", "test_auth.py", "Data_Engineer", "workflow_orchestration_o4-mini_group0_3", "librarybench", ""], "setup": {"duration": 0.0004155000060563907, "outcome": "passed"}, "call": {"duration": 0.0003001669974764809, "outcome": "passed"}, "teardown": {"duration": 0.00019220799731556326, "outcome": "passed"}}, {"nodeid": "workflow_orchestration_o4-mini_group0_3/Data_Engineer/test_scheduler.py::test_scheduler_runs_periodically", "lineno": 4, "outcome": "passed", "keywords": ["test_scheduler_runs_periodically", "test_scheduler.py", "Data_Engineer", "workflow_orchestration_o4-mini_group0_3", "librarybench", ""], "setup": {"duration": 0.0004436249873833731, "outcome": "passed"}, "call": {"duration": 0.3547714169981191, "outcome": "passed"}, "teardown": {"duration": 0.000376958996639587, "outcome": "passed"}}]}