Traceback (most recent call last):
  File "/Users/celine/miniconda3/envs/library/lib/python3.13/site-packages/_pytest/config/__init__.py", line 858, in import_plugin
    __import__(importspec)
    ~~~~~~~~~~^^^^^^^^^^^^
ModuleNotFoundError: No module named 'pytest_asyncio'

The above exception was the direct cause of the following exception:

Traceback (most recent call last):
  File "/Users/celine/miniconda3/envs/library/bin/pytest", line 8, in <module>
    sys.exit(console_main())
             ~~~~~~~~~~~~^^
  File "/Users/celine/miniconda3/envs/library/lib/python3.13/site-packages/_pytest/config/__init__.py", line 201, in console_main
    code = main()
  File "/Users/celine/miniconda3/envs/library/lib/python3.13/site-packages/_pytest/config/__init__.py", line 156, in main
    config = _prepareconfig(args, plugins)
  File "/Users/celine/miniconda3/envs/library/lib/python3.13/site-packages/_pytest/config/__init__.py", line 341, in _prepareconfig
    config = pluginmanager.hook.pytest_cmdline_parse(
        pluginmanager=pluginmanager, args=args
    )
  File "/Users/celine/miniconda3/envs/library/lib/python3.13/site-packages/pluggy/_hooks.py", line 513, in __call__
    return self._hookexec(self.name, self._hookimpls.copy(), kwargs, firstresult)
           ~~~~~~~~~~~~~~^^^^^^^^^^^^^^^^^^^^^^^^^^^^^^^^^^^^^^^^^^^^^^^^^^^^^^^^
  File "/Users/celine/miniconda3/envs/library/lib/python3.13/site-packages/pluggy/_manager.py", line 120, in _hookexec
    return self._inner_hookexec(hook_name, methods, kwargs, firstresult)
           ~~~~~~~~~~~~~~~~~~~~^^^^^^^^^^^^^^^^^^^^^^^^^^^^^^^^^^^^^^^^^
  File "/Users/celine/miniconda3/envs/library/lib/python3.13/site-packages/pluggy/_callers.py", line 139, in _multicall
    raise exception.with_traceback(exception.__traceback__)
  File "/Users/celine/miniconda3/envs/library/lib/python3.13/site-packages/pluggy/_callers.py", line 122, in _multicall
    teardown.throw(exception)  # type: ignore[union-attr]
    ~~~~~~~~~~~~~~^^^^^^^^^^^
  File "/Users/celine/miniconda3/envs/library/lib/python3.13/site-packages/_pytest/helpconfig.py", line 105, in pytest_cmdline_parse
    config = yield
             ^^^^^
  File "/Users/celine/miniconda3/envs/library/lib/python3.13/site-packages/pluggy/_callers.py", line 103, in _multicall
    res = hook_impl.function(*args)
  File "/Users/celine/miniconda3/envs/library/lib/python3.13/site-packages/_pytest/config/__init__.py", line 1140, in pytest_cmdline_parse
    self.parse(args)
    ~~~~~~~~~~^^^^^^
  File "/Users/celine/miniconda3/envs/library/lib/python3.13/site-packages/_pytest/config/__init__.py", line 1494, in parse
    self._preparse(args, addopts=addopts)
    ~~~~~~~~~~~~~~^^^^^^^^^^^^^^^^^^^^^^^
  File "/Users/celine/miniconda3/envs/library/lib/python3.13/site-packages/_pytest/config/__init__.py", line 1398, in _preparse
    self.hook.pytest_load_initial_conftests(
    ~~~~~~~~~~~~~~~~~~~~~~~~~~~~~~~~~~~~~~~^
        early_config=self, args=args, parser=self._parser
        ^^^^^^^^^^^^^^^^^^^^^^^^^^^^^^^^^^^^^^^^^^^^^^^^^
    )
    ^
  File "/Users/celine/miniconda3/envs/library/lib/python3.13/site-packages/pluggy/_hooks.py", line 513, in __call__
    return self._hookexec(self.name, self._hookimpls.copy(), kwargs, firstresult)
           ~~~~~~~~~~~~~~^^^^^^^^^^^^^^^^^^^^^^^^^^^^^^^^^^^^^^^^^^^^^^^^^^^^^^^^
  File "/Users/celine/miniconda3/envs/library/lib/python3.13/site-packages/pluggy/_manager.py", line 120, in _hookexec
    return self._inner_hookexec(hook_name, methods, kwargs, firstresult)
           ~~~~~~~~~~~~~~~~~~~~^^^^^^^^^^^^^^^^^^^^^^^^^^^^^^^^^^^^^^^^^
  File "/Users/celine/miniconda3/envs/library/lib/python3.13/site-packages/pluggy/_callers.py", line 139, in _multicall
    raise exception.with_traceback(exception.__traceback__)
  File "/Users/celine/miniconda3/envs/library/lib/python3.13/site-packages/pluggy/_callers.py", line 122, in _multicall
    teardown.throw(exception)  # type: ignore[union-attr]
    ~~~~~~~~~~~~~~^^^^^^^^^^^
  File "/Users/celine/miniconda3/envs/library/lib/python3.13/site-packages/_pytest/warnings.py", line 151, in pytest_load_initial_conftests
    return (yield)
            ^^^^^
  File "/Users/celine/miniconda3/envs/library/lib/python3.13/site-packages/pluggy/_callers.py", line 122, in _multicall
    teardown.throw(exception)  # type: ignore[union-attr]
    ~~~~~~~~~~~~~~^^^^^^^^^^^
  File "/Users/celine/miniconda3/envs/library/lib/python3.13/site-packages/_pytest/capture.py", line 172, in pytest_load_initial_conftests
    yield
  File "/Users/celine/miniconda3/envs/library/lib/python3.13/site-packages/pluggy/_callers.py", line 103, in _multicall
    res = hook_impl.function(*args)
  File "/Users/celine/miniconda3/envs/library/lib/python3.13/site-packages/_pytest/config/__init__.py", line 1222, in pytest_load_initial_conftests
    self.pluginmanager._set_initial_conftests(
    ~~~~~~~~~~~~~~~~~~~~~~~~~~~~~~~~~~~~~~~~~^
        args=args,
        ^^^^^^^^^^
    ...<8 lines>...
        ),
        ^^
    )
    ^
  File "/Users/celine/miniconda3/envs/library/lib/python3.13/site-packages/_pytest/config/__init__.py", line 581, in _set_initial_conftests
    self._try_load_conftest(
    ~~~~~~~~~~~~~~~~~~~~~~~^
        anchor,
        ^^^^^^^
    ...<2 lines>...
        consider_namespace_packages=consider_namespace_packages,
        ^^^^^^^^^^^^^^^^^^^^^^^^^^^^^^^^^^^^^^^^^^^^^^^^^^^^^^^^
    )
    ^
  File "/Users/celine/miniconda3/envs/library/lib/python3.13/site-packages/_pytest/config/__init__.py", line 619, in _try_load_conftest
    self._loadconftestmodules(
    ~~~~~~~~~~~~~~~~~~~~~~~~~^
        anchor,
        ^^^^^^^
    ...<2 lines>...
        consider_namespace_packages=consider_namespace_packages,
        ^^^^^^^^^^^^^^^^^^^^^^^^^^^^^^^^^^^^^^^^^^^^^^^^^^^^^^^^
    )
    ^
  File "/Users/celine/miniconda3/envs/library/lib/python3.13/site-packages/_pytest/config/__init__.py", line 659, in _loadconftestmodules
    mod = self._importconftest(
        conftestpath,
    ...<2 lines>...
        consider_namespace_packages=consider_namespace_packages,
    )
  File "/Users/celine/miniconda3/envs/library/lib/python3.13/site-packages/_pytest/config/__init__.py", line 735, in _importconftest
    self.consider_conftest(mod, registration_name=conftestpath_plugin_name)
    ~~~~~~~~~~~~~~~~~~~~~~^^^^^^^^^^^^^^^^^^^^^^^^^^^^^^^^^^^^^^^^^^^^^^^^^
  File "/Users/celine/miniconda3/envs/library/lib/python3.13/site-packages/_pytest/config/__init__.py", line 816, in consider_conftest
    self.register(conftestmodule, name=registration_name)
    ~~~~~~~~~~~~~^^^^^^^^^^^^^^^^^^^^^^^^^^^^^^^^^^^^^^^^
  File "/Users/celine/miniconda3/envs/library/lib/python3.13/site-packages/_pytest/config/__init__.py", line 512, in register
    self.consider_module(plugin)
    ~~~~~~~~~~~~~~~~~~~~^^^^^^^^
  File "/Users/celine/miniconda3/envs/library/lib/python3.13/site-packages/_pytest/config/__init__.py", line 824, in consider_module
    self._import_plugin_specs(getattr(mod, "pytest_plugins", []))
    ~~~~~~~~~~~~~~~~~~~~~~~~~^^^^^^^^^^^^^^^^^^^^^^^^^^^^^^^^^^^^
  File "/Users/celine/miniconda3/envs/library/lib/python3.13/site-packages/_pytest/config/__init__.py", line 831, in _import_plugin_specs
    self.import_plugin(import_spec)
    ~~~~~~~~~~~~~~~~~~^^^^^^^^^^^^^
  File "/Users/celine/miniconda3/envs/library/lib/python3.13/site-packages/_pytest/config/__init__.py", line 860, in import_plugin
    raise ImportError(
        f'Error importing plugin "{modname}": {e.args[0]}'
    ).with_traceback(e.__traceback__) from e
  File "/Users/celine/miniconda3/envs/library/lib/python3.13/site-packages/_pytest/config/__init__.py", line 858, in import_plugin
    __import__(importspec)
    ~~~~~~~~~~^^^^^^^^^^^^
ImportError: Error importing plugin "pytest_asyncio": No module named 'pytest_asyncio'
